Workbook

Sheet CLP_Epidemiology
B1: Country | C1: Year | D1: Birth Population | E1: Total Population | F1: Incidence Rate (per100k), 2021 | G1: Number of Cases per Total Population | H1: Incidence Lower | I1: Number of Cases per Total Population (Lower) | J1: Incidence Upper | K1: Number of Cases per Total Population (Upper) | L1: Adjusted Incidence per Birth Population | M1: Adjusted Incidence Rate per Birth Population (Lower) | N1: Adjusted Incidence Rate per Birth Population (Upper) | O1: DALY Rate (per 100k), 2021 | P1: Number of DALY's per 100k | Q1: DALY Lower | R1: Number of DALY's per 100k (Lower) | S1: DALY Upper | T1: Number of DALY's per 100k (Upper) | U1: Adjusted Incidence of DALYs per Birth Population | V1: Adjusted Incidence of DALYs per Birth Population (Lower) | W1: Adjusted Incidence of DALYs per Birth Population (Upper | X1: Notes
A2: a | B2: Afghanistan | C2: 2021 | D2: =674131.5+704952.5 -> 1379084 | E2: 40000412 | F2: 6.21 | G2: =(F2/100000)*E2 -> 2484.0256 | H2: 4.66 | I2: =(H2/100000)*E2 -> 1864.0192 | J2: 8.25 | K2: =(J2/100000)*E2 -> 3300.034 | L2: =(G2/D2)*100000 -> 180.12141 | M2: =(I2/D2)*100000 -> 135.16357 | N2: =(K2/D2)*100000 -> 239.29173 | O2: 37.21 | P2: =(O2/100000)*E2 -> 14884.153 | Q2: 7.14 | R2: =(Q2/100000)*E2 -> 2856.0294 | S2: 186.55 | T2: =(S2/100000)*E2 -> 74620.769 | U2: =(P2/D2)*100000 -> 1079.2782 | V2: =(R2/D2)*100000 -> 207.09612 | W2: =(T2/D2)*100000 -> 5410.8936
A3: b | B3: Afghanistan | C3: 2030 | D3: 1521091 | E3: 50039402 | F3: 6.21 | G3: =(F3/100000)*E3 -> 3107.4469 | H3: 4.66 | I3: =(H3/100000)*E3 -> 2331.8361 | J3: 8.25 | K3: =(J3/100000)*E3 -> 4128.2507 | L3: =(L2/100000)*D3 -> 2739.8106 | M3: =(I3*D3)/100000 -> 35469.35 | N3: =(K3*D3)/100000 -> 62794.449 | O3: 37.21 | Q3: 7.14 | S3: 186.55 | U3: =(O3*D3)/100000 -> 565.99796 | V3: =(Q3*D3)/100000 -> 108.6059 | W3: =(S3*D3)/100000 -> 2837.5953 | X3: Rates per 100,000 | Z3: =ROUND(F3, 0) & " (" & ROUND(H3, 0) & "-" & ROUND(J3, 0) & ")" -> 6 (5-8) | AA3: =ROUND(L3, 0) & " (" & ROUND(M3, 0) & "-" & ROUND(N3, 0) & ")" -> 2740 (35469-62794) | AB3: =ROUND(O3, 0) & " (" & ROUND(Q3, 0) & "-" & ROUND(S3, 0) & ")" -> 37 (7-187) | AC3: =ROUND(U3, 0) & " (" & ROUND(V3, 0) & "-" & ROUND(W3, 0) & ")" -> 566 (109-2838)
A4: c | B4: Afghanistan | C4: 2040 | D4: 1653659 | E4: 63347870 | F4: 6.21 | G4: =(F4/100000)*E4 -> 3933.9027 | H4: 4.66 | I4: =(H4/100000)*E4 -> 2952.0107 | J4: 8.25 | K4: =(J4/100000)*E4 -> 5226.1993 | L4: =(G4/D4)*100000 -> 237.89081 | M4: =(I4*D4)/100000 -> 48816.191 | N4: =(K4*D4)/100000 -> 86423.515 | O4: 37.21 | Q4: 7.14 | S4: 186.55 | U4: =(O4*D4)/100000 -> 615.32651 | V4: =(Q4*D4)/100000 -> 118.07125 | W4: =(S4*D4)/100000 -> 3084.9009 | X4: Using Rate Metric | Z4: =ROUND(F4, 0) & " (" & ROUND(H4, 0) & "-" & ROUND(J4, 0) & ")" -> 6 (5-8) | AA4: =ROUND(L4, 0) & " (" & ROUND(M4, 0) & "-" & ROUND(N4, 0) & ")" -> 238 (48816-86424) | AB4: =ROUND(O4, 0) & " (" & ROUND(Q4, 0) & "-" & ROUND(S4, 0) & ")" -> 37 (7-187) | AC4: =ROUND(U4, 0) & " (" & ROUND(V4, 0) & "-" & ROUND(W4, 0) & ")" -> 615 (118-3085)
A5: d | B5: Afghanistan | C5: 2050 | D5: 1771185 | E5: 76885135 | F5: 6.21 | G5: =(F5/100000)*E5 -> 4774.5669 | H5: 4.66 | I5: =(H5/100000)*E5 -> 3582.8473 | J5: 8.25 | K5: =(J5/100000)*E5 -> 6343.0236 | L5: =(G5/D5)*100000 -> 269.56907 | M5: =(I5*D5)/100000 -> 63458.854 | N5: =(K5*D5)/100000 -> 112346.68 | O5: 37.21 | P5: =(O5/100000)*E5 -> 28608.959 | Q5: 7.14 | R5: =(Q5/100000)*E5 -> 5489.5986 | S5: 186.55 | T5: =(S5/100000)*E5 -> 143429.22 | U5: =(O5*D5)/100000 -> 659.05794 | V5: =(Q5*D5)/100000 -> 126.46261 | W5: =(S5*D5)/100000 -> 3304.1456
A6: a | B6: Algeria | C6: 2021 | D6: =468124.5+488067 -> 956191.5 | E6: 44761099 | F6: 3 | G6: =(F6/100000)*E6 -> 1342.833 | H6: 2.24 | I6: =(H6/100000)*E6 -> 1002.6486 | J6: 4.04 | K6: =(J6/100000)*E6 -> 1808.3484 | L6: =(G6/D6)*100000 -> 140.43557 | M6: =(I6/D6)*100000 -> 104.85856 | N6: =(K6/D6)*100000 -> 189.1199 | O6: 7.31 | P6: =(O6/100000)*E6 -> 3272.0363 | Q6: 5.04 | R6: =(Q6/100000)*E6 -> 2255.9594 | S6: 10.72 | T6: =(S6/100000)*E6 -> 4798.3898 | U6: =(P6/D6)*100000 -> 342.19467 | V6: =(R6/D6)*100000 -> 235.93176 | W6: =(T6/D6)*100000 -> 501.8231
A7: b | B7: Algeria | C7: 2030 | D7: =374961+391323 -> 766284 | E7: 50154166 | F7: 3 | G7: =(F7/100000)*E7 -> 1504.625 | H7: 2.24 | I7: =(H7/100000)*E7 -> 1123.4533 | J7: 4.04 | K7: =(J7/100000)*E7 -> 2026.2283 | L7: =(G7/D7)*100000 -> 196.35344 | M7: =(I7*D7)/100000 -> 8608.843 | N7: =(K7*D7)/100000 -> 15526.663 | O7: 7.31 | Q7: 5.04 | S7: 10.72 | U7: =(O7*D7)/100000 -> 56.01536 | V7: =(Q7*D7)/100000 -> 38.620714 | W7: =(S7*D7)/100000 -> 82.145645 | Z7: =ROUND(F7, 0) & " (" & ROUND(H7, 0) & "-" & ROUND(J7, 0) & ")" -> 3 (2-4) | AA7: =ROUND(L7, 0) & " (" & ROUND(M7, 0) & "-" & ROUND(N7, 0) & ")" -> 196 (8609-15527) | AB7: =ROUND(O7, 0) & " (" & ROUND(Q7, 0) & "-" & ROUND(S7, 0) & ")" -> 7 (5-11) | AC7: =ROUND(U7, 0) & " (" & ROUND(V7, 0) & "-" & ROUND(W7, 0) & ")" -> 56 (39-82)
A8: c | B8: Algeria | C8: 2040 | D8: =401278+419330 -> 820608 | E8: 54873476 | F8: 3 | G8: =(F8/100000)*E8 -> 1646.2043 | H8: 2.24 | I8: =(H8/100000)*E8 -> 1229.1659 | J8: 4.04 | K8: =(J8/100000)*E8 -> 2216.8884 | L8: =(G8/D8)*100000 -> 200.60788 | M8: =(I8*D8)/100000 -> 10086.633 | N8: =(K8*D8)/100000 -> 18191.964 | O8: 7.31 | Q8: 5.04 | S8: 10.72 | U8: =(O8*D8)/100000 -> 59.986445 | V8: =(Q8*D8)/100000 -> 41.358643 | W8: =(S8*D8)/100000 -> 87.969178 | Z8: =ROUND(F8, 0) & " (" & ROUND(H8, 0) & "-" & ROUND(J8, 0) & ")" -> 3 (2-4) | AA8: =ROUND(L8, 0) & " (" & ROUND(M8, 0) & "-" & ROUND(N8, 0) & ")" -> 201 (10087-18192) | AB8: =ROUND(O8, 0) & " (" & ROUND(Q8, 0) & "-" & ROUND(S8, 0) & ")" -> 7 (5-11) | AC8: =ROUND(U8, 0) & " (" & ROUND(V8, 0) & "-" & ROUND(W8, 0) & ")" -> 60 (41-88)
A9: d | B9: Algeria | C9: 2050 | D9: =419100+438415 -> 857515 | E9: 59565554 | F9: 3 | G9: =(F9/100000)*E9 -> 1786.9666 | H9: 2.24 | I9: =(H9/100000)*E9 -> 1334.2684 | J9: 4.04 | K9: =(J9/100000)*E9 -> 2406.4484 | L9: =(G9/D9)*100000 -> 208.38896 | M9: =(I9*D9)/100000 -> 11441.552 | N9: =(K9*D9)/100000 -> 20635.656 | O9: 7.31 | P9: =(O9/100000)*E9 -> 4354.242 | Q9: 5.04 | R9: =(Q9/100000)*E9 -> 3002.1039 | S9: 10.72 | T9: =(S9/100000)*E9 -> 6385.4274 | U9: =(O9*D9)/100000 -> 62.684346 | V9: =(Q9*D9)/100000 -> 43.218756 | W9: =(S9*D9)/100000 -> 91.925608
A10: a | B10: Bahrain | C10: 2021 | D10: =9267.5+9565.5 -> 18833 | E10: 1504365 | F10: 1.67 | G10: =(F10/100000)*E10 -> 25.122895 | H10: 1.25 | I10: =(H10/100000)*E10 -> 18.804562 | J10: 2.24 | K10: =(J10/100000)*E10 -> 33.697776 | L10: =(G10/D10)*100000 -> 133.39827 | M10: =(I10/D10)*100000 -> 99.849002 | N10: =(K10/D10)*100000 -> 178.92941 | O10: 5.52 | P10: =(O10/100000)*E10 -> 83.040948 | Q10: 3.42 | R10: =(Q10/100000)*E10 -> 51.449283 | S10: 8.22 | T10: =(S10/100000)*E10 -> 123.6588 | U10: =(P10/D10)*100000 -> 440.93319 | V10: =(R10/D10)*100000 -> 273.18687 | W10: =(T10/D10)*100000 -> 656.60704
A11: b | B11: Bahrain | C11: 2030 | D11: =10331+10695 -> 21026 | E11: 1733610 | F11: 1.67 | G11: =(F11/100000)*E11 -> 28.951287 | H11: 1.25 | I11: =(H11/100000)*E11 -> 21.670125 | J11: 2.24 | K11: =(J11/100000)*E11 -> 38.832864 | L11: =(G11/D11)*100000 -> 137.69279 | M11: =(I11*D11)/100000 -> 4.5563605 | N11: =(K11*D11)/100000 -> 8.164998 | O11: 5.52 | Q11: 3.42 | S11: 8.22 | U11: =(O11*D11)/100000 -> 1.1606352 | V11: =(Q11*D11)/100000 -> 0.7190892 | W11: =(S11*D11)/100000 -> 1.7283372 | Z11: =ROUND(F11, 0) & " (" & ROUND(H11, 0) & "-" & ROUND(J11, 0) & ")" -> 2 (1-2) | AA11: =ROUND(L11, 0) & " (" & ROUND(M11, 0) & "-" & ROUND(N11, 0) & ")" -> 138 (5-8) | AB11: =ROUND(O11, 0) & " (" & ROUND(Q11, 0) & "-" & ROUND(S11, 0) & ")" -> 6 (3-8) | AC11: =ROUND(U11, 0) & " (" & ROUND(V11, 0) & "-" & ROUND(W11, 0) & ")" -> 1 (1-2)
A12: c | B12: Bahrain | C12: 2040 | D12: =11484+11875 -> 23359 | E12: 1914988 | F12: 1.67 | G12: =(F12/100000)*E12 -> 31.9803 | H12: 1.25 | I12: =(H12/100000)*E12 -> 23.93735 | J12: 2.24 | K12: =(J12/100000)*E12 -> 42.895731 | L12: =(G12/D12)*100000 -> 136.90783 | M12: =(I12*D12)/100000 -> 5.5915256 | N12: =(K12*D12)/100000 -> 10.020014 | O12: 5.52 | Q12: 3.42 | S12: 8.22 | U12: =(O12*D12)/100000 -> 1.2894168 | V12: =(Q12*D12)/100000 -> 0.7988778 | W12: =(S12*D12)/100000 -> 1.9201098 | Z12: =ROUND(F12, 0) & " (" & ROUND(H12, 0) & "-" & ROUND(J12, 0) & ")" -> 2 (1-2) | AA12: =ROUND(L12, 0) & " (" & ROUND(M12, 0) & "-" & ROUND(N12, 0) & ")" -> 137 (6-10) | AB12: =ROUND(O12, 0) & " (" & ROUND(Q12, 0) & "-" & ROUND(S12, 0) & ")" -> 6 (3-8) | AC12: =ROUND(U12, 0) & " (" & ROUND(V12, 0) & "-" & ROUND(W12, 0) & ")" -> 1 (1-2)
A13: d | B13: Bahrain | C13: 2050 | D13: =11965+12358 -> 24323 | E13: 2098576 | F13: 1.67 | G13: =(F13/100000)*E13 -> 35.046219 | H13: 1.25 | I13: =(H13/100000)*E13 -> 26.2322 | J13: 2.24 | K13: =(J13/100000)*E13 -> 47.008102 | L13: =(G13/D13)*100000 -> 144.08675 | M13: =(I13*D13)/100000 -> 6.380458 | N13: =(K13*D13)/100000 -> 11.433781 | O13: 5.52 | P13: =(O13/100000)*E13 -> 115.8414 | Q13: 3.42 | R13: =(Q13/100000)*E13 -> 71.771299 | S13: 8.22 | T13: =(S13/100000)*E13 -> 172.50295 | U13: =(O13*D13)/100000 -> 1.3426296 | V13: =(Q13*D13)/100000 -> 0.8318466 | W13: =(S13*D13)/100000 -> 1.9993506
A14: a | B14: Egypt | C14: 2021 | D14: =1142649+1200963 -> 2343612 | E14: 110957008 | F14: 3.43 | G14: =(F14/100000)*E14 -> 3805.8254 | H14: 2.63 | I14: =(H14/100000)*E14 -> 2918.1693 | J14: 4.59 | K14: =(J14/100000)*E14 -> 5092.9267 | L14: =(G14/D14)*100000 -> 162.39144 | M14: =(I14/D14)*100000 -> 124.51589 | N14: =(K14/D14)*100000 -> 217.311 | O14: 7.86 | P14: =(O14/100000)*E14 -> 8721.2208 | Q14: 5.28 | R14: =(Q14/100000)*E14 -> 5858.53 | S14: 11.15 | T14: =(S14/100000)*E14 -> 12371.706 | U14: =(P14/D14)*100000 -> 372.12733 | V14: =(R14/D14)*100000 -> 249.97867 | W14: =(T14/D14)*100000 -> 527.89055
A15: b | B15: Egypt | C15: 2030 | D15: =1213206+1278324 -> 2491530 | E15: 127139322 | F15: 3.43 | G15: =(F15/100000)*E15 -> 4360.8787 | H15: 2.63 | I15: =(H15/100000)*E15 -> 3343.7642 | J15: 4.59 | K15: =(J15/100000)*E15 -> 5835.6949 | L15: =(G15/D15)*100000 -> 175.02815 | M15: =(I15*D15)/100000 -> 83310.887 | N15: =(K15*D15)/100000 -> 145398.09 | O15: 7.86 | Q15: 5.28 | S15: 11.15 | U15: =(O15*D15)/100000 -> 195.83426 | V15: =(Q15*D15)/100000 -> 131.55278 | W15: =(S15*D15)/100000 -> 277.80559 | Z15: =ROUND(F15, 0) & " (" & ROUND(H15, 0) & "-" & ROUND(J15, 0) & ")" -> 3 (3-5) | AA15: =ROUND(L15, 0) & " (" & ROUND(M15, 0) & "-" & ROUND(N15, 0) & ")" -> 175 (83311-145398) | AB15: =ROUND(O15, 0) & " (" & ROUND(Q15, 0) & "-" & ROUND(S15, 0) & ")" -> 8 (5-11) | AC15: =ROUND(U15, 0) & " (" & ROUND(V15, 0) & "-" & ROUND(W15, 0) & ")" -> 196 (132-278)
A16: c | B16: Egypt | C16: 2040 | D16: =1327238+1399803 -> 2727041 | E16: 145213654 | F16: 3.43 | G16: =(F16/100000)*E16 -> 4980.8283 | H16: 2.63 | I16: =(H16/100000)*E16 -> 3819.1191 | J16: 4.59 | K16: =(J16/100000)*E16 -> 6665.3067 | L16: =(G16/D16)*100000 -> 182.64589 | M16: =(I16*D16)/100000 -> 104148.94 | N16: =(K16*D16)/100000 -> 181765.65 | O16: 7.86 | Q16: 5.28 | S16: 11.15 | U16: =(O16*D16)/100000 -> 214.34542 | V16: =(Q16*D16)/100000 -> 143.98776 | W16: =(S16*D16)/100000 -> 304.06507 | Z16: =ROUND(F16, 0) & " (" & ROUND(H16, 0) & "-" & ROUND(J16, 0) & ")" -> 3 (3-5) | AA16: =ROUND(L16, 0) & " (" & ROUND(M16, 0) & "-" & ROUND(N16, 0) & ")" -> 183 (104149-181766) | AB16: =ROUND(O16, 0) & " (" & ROUND(Q16, 0) & "-" & ROUND(S16, 0) & ")" -> 8 (5-11) | AC16: =ROUND(U16, 0) & " (" & ROUND(V16, 0) & "-" & ROUND(W16, 0) & ")" -> 214 (144-304)
A17: d | B17: Egypt | C17: 2050 | D17: =1250892+1319902 -> 2570794 | E17: 161630192 | F17: 3.43 | G17: =(F17/100000)*E17 -> 5543.9156 | H17: 2.63 | I17: =(H17/100000)*E17 -> 4250.8741 | J17: 4.59 | K17: =(J17/100000)*E17 -> 7418.8258 | L17: =(G17/D17)*100000 -> 215.64993 | M17: =(I17*D17)/100000 -> 109281.21 | N17: =(K17*D17)/100000 -> 190722.73 | O17: 7.86 | P17: =(O17/100000)*E17 -> 12704.133 | Q17: 5.28 | R17: =(Q17/100000)*E17 -> 8534.0741 | S17: 11.15 | T17: =(S17/100000)*E17 -> 18021.766 | U17: =(O17*D17)/100000 -> 202.06441 | V17: =(Q17*D17)/100000 -> 135.73792 | W17: =(S17*D17)/100000 -> 286.64353
A18: a | B18: Iran | C18: 2021 | D18: =589147+620407 -> 1209554 | E18: 88455488 | F18: 1.48 | G18: =(F18/100000)*E18 -> 1309.1412 | H18: 1.12 | I18: =(H18/100000)*E18 -> 990.70147 | J18: 2.03 | K18: =(J18/100000)*E18 -> 1795.6464 | L18: =(G18/D18)*100000 -> 108.23338 | M18: =(I18/D18)*100000 -> 81.906344 | N18: =(K18/D18)*100000 -> 148.45525 | O18: 5.26 | P18: =(O18/100000)*E18 -> 4652.7587 | Q18: 3.5 | R18: =(Q18/100000)*E18 -> 3095.9421 | S18: 7.55 | T18: =(S18/100000)*E18 -> 6678.3893 | U18: =(P18/D18)*100000 -> 384.6673 | V18: =(R18/D18)*100000 -> 255.95733 | W18: =(T18/D18)*100000 -> 552.13652
A19: b | B19: Iran | C19: 2030 | D19: =505962+530579 -> 1036541 | E19: 95486667 | F19: 1.48 | G19: =(F19/100000)*E19 -> 1413.2027 | H19: 1.12 | I19: =(H19/100000)*E19 -> 1069.4507 | J19: 2.03 | K19: =(J19/100000)*E19 -> 1938.3793 | L19: =(G19/D19)*100000 -> 136.33833 | M19: =(I19*D19)/100000 -> 11085.295 | N19: =(K19*D19)/100000 -> 20092.097 | O19: 5.26 | Q19: 3.5 | S19: 7.55 | U19: =(O19*D19)/100000 -> 54.522057 | V19: =(Q19*D19)/100000 -> 36.278935 | W19: =(S19*D19)/100000 -> 78.258846 | Z19: =ROUND(F19, 0) & " (" & ROUND(H19, 0) & "-" & ROUND(J19, 0) & ")" -> 1 (1-2) | AA19: =ROUND(L19, 0) & " (" & ROUND(M19, 0) & "-" & ROUND(N19, 0) & ")" -> 136 (11085-20092) | AB19: =ROUND(O19, 0) & " (" & ROUND(Q19, 0) & "-" & ROUND(S19, 0) & ")" -> 5 (4-8) | AC19: =ROUND(U19, 0) & " (" & ROUND(V19, 0) & "-" & ROUND(W19, 0) & ")" -> 55 (36-78)
A20: c | B20: Iran | C20: 2040 | D20: =508605+533053 -> 1041658 | E20: 99524277 | F20: 1.48 | G20: =(F20/100000)*E20 -> 1472.9593 | H20: 1.12 | I20: =(H20/100000)*E20 -> 1114.6719 | J20: 2.03 | K20: =(J20/100000)*E20 -> 2020.3428 | L20: =(G20/D20)*100000 -> 141.40527 | M20: =(I20*D20)/100000 -> 11611.069 | N20: =(K20*D20)/100000 -> 21045.063 | O20: 5.26 | Q20: 3.5 | S20: 7.55 | U20: =(O20*D20)/100000 -> 54.791211 | V20: =(Q20*D20)/100000 -> 36.45803 | W20: =(S20*D20)/100000 -> 78.645179 | Z20: =ROUND(F20, 0) & " (" & ROUND(H20, 0) & "-" & ROUND(J20, 0) & ")" -> 1 (1-2) | AA20: =ROUND(L20, 0) & " (" & ROUND(M20, 0) & "-" & ROUND(N20, 0) & ")" -> 141 (11611-21045) | AB20: =ROUND(O20, 0) & " (" & ROUND(Q20, 0) & "-" & ROUND(S20, 0) & ")" -> 5 (4-8) | AC20: =ROUND(U20, 0) & " (" & ROUND(V20, 0) & "-" & ROUND(W20, 0) & ")" -> 55 (36-79)
A21: d | B21: Iran | C21: 2050 | D21: =482638+505938 -> 988576 | E21: 101861993 | F21: 1.48 | G21: =(F21/100000)*E21 -> 1507.5575 | H21: 1.12 | I21: =(H21/100000)*E21 -> 1140.8543 | J21: 2.03 | K21: =(J21/100000)*E21 -> 2067.7985 | L21: =(G21/D21)*100000 -> 152.49789 | M21: =(I21*D21)/100000 -> 11278.212 | N21: =(K21*D21)/100000 -> 20441.759 | O21: 5.26 | P21: =(O21/100000)*E21 -> 5357.9408 | Q21: 3.5 | R21: =(Q21/100000)*E21 -> 3565.1698 | S21: 7.55 | T21: =(S21/100000)*E21 -> 7690.5805 | U21: =(O21*D21)/100000 -> 51.999098 | V21: =(Q21*D21)/100000 -> 34.60016 | W21: =(S21*D21)/100000 -> 74.637488
A22: a | B22: Iraq | C22: 2021 | D22: =542916+571526.5 -> 1114442.5 | E22: 43071211 | F22: 3.53 | G22: =(F22/100000)*E22 -> 1520.4137 | H22: 2.61 | I22: =(H22/100000)*E22 -> 1124.1586 | J22: 4.87 | K22: =(J22/100000)*E22 -> 2097.568 | L22: =(G22/D22)*100000 -> 136.42819 | M22: =(I22/D22)*100000 -> 100.87184 | N22: =(K22/D22)*100000 -> 188.2168 | O22: 6.58 | P22: =(O22/100000)*E22 -> 2834.0857 | Q22: 4.35 | R22: =(Q22/100000)*E22 -> 1873.5977 | S22: 9.6 | T22: =(S22/100000)*E22 -> 4134.8363 | U22: =(P22/D22)*100000 -> 254.30524 | V22: =(R22/D22)*100000 -> 168.11973 | W22: =(T22/D22)*100000 -> 371.02284
A23: b | B23: Iraq | C23: 2030 | D23: =597042+627808 -> 1224850 | E23: 51937208 | F23: 3.53 | G23: =(F23/100000)*E23 -> 1833.3834 | H23: 2.61 | I23: =(H23/100000)*E23 -> 1355.5611 | J23: 4.87 | K23: =(J23/100000)*E23 -> 2529.342 | L23: =(G23/D23)*100000 -> 149.68228 | M23: =(I23*D23)/100000 -> 16603.59 | N23: =(K23*D23)/100000 -> 30980.646 | O23: 6.58 | Q23: 4.35 | S23: 9.6 | U23: =(O23*D23)/100000 -> 80.59513 | V23: =(Q23*D23)/100000 -> 53.280975 | W23: =(S23*D23)/100000 -> 117.5856 | Z23: =ROUND(F23, 0) & " (" & ROUND(H23, 0) & "-" & ROUND(J23, 0) & ")" -> 4 (3-5) | AA23: =ROUND(L23, 0) & " (" & ROUND(M23, 0) & "-" & ROUND(N23, 0) & ")" -> 150 (16604-30981) | AB23: =ROUND(O23, 0) & " (" & ROUND(Q23, 0) & "-" & ROUND(S23, 0) & ")" -> 7 (4-10) | AC23: =ROUND(U23, 0) & " (" & ROUND(V23, 0) & "-" & ROUND(W23, 0) & ")" -> 81 (53-118)
A24: c | B24: Iraq | C24: 2040 | D24: =644831+677866 -> 1322697 | E24: 62223211 | F24: 3.53 | G24: =(F24/100000)*E24 -> 2196.4793 | H24: 2.61 | I24: =(H24/100000)*E24 -> 1624.0258 | J24: 4.87 | K24: =(J24/100000)*E24 -> 3030.2704 | L24: =(G24/D24)*100000 -> 166.06066 | M24: =(I24*D24)/100000 -> 21480.941 | N24: =(K24*D24)/100000 -> 40081.295 | O24: 6.58 | Q24: 4.35 | S24: 9.6 | U24: =(O24*D24)/100000 -> 87.033463 | V24: =(Q24*D24)/100000 -> 57.53732 | W24: =(S24*D24)/100000 -> 126.97891 | Z24: =ROUND(F24, 0) & " (" & ROUND(H24, 0) & "-" & ROUND(J24, 0) & ")" -> 4 (3-5) | AA24: =ROUND(L24, 0) & " (" & ROUND(M24, 0) & "-" & ROUND(N24, 0) & ")" -> 166 (21481-40081) | AB24: =ROUND(O24, 0) & " (" & ROUND(Q24, 0) & "-" & ROUND(S24, 0) & ")" -> 7 (4-10) | AC24: =ROUND(U24, 0) & " (" & ROUND(V24, 0) & "-" & ROUND(W24, 0) & ")" -> 87 (58-127)
A25: d | B25: Iraq | C25: 2050 | D25: =644321+677667 -> 1321988 | E25: 71928750 | F25: 3.53 | G25: =(F25/100000)*E25 -> 2539.0849 | H25: 2.61 | I25: =(H25/100000)*E25 -> 1877.3404 | J25: 4.87 | K25: =(J25/100000)*E25 -> 3502.9301 | L25: =(G25/D25)*100000 -> 192.06565 | M25: =(I25*D25)/100000 -> 24818.214 | N25: =(K25*D25)/100000 -> 46308.316 | O25: 6.58 | P25: =(O25/100000)*E25 -> 4732.9118 | Q25: 4.35 | R25: =(Q25/100000)*E25 -> 3128.9006 | S25: 9.6 | T25: =(S25/100000)*E25 -> 6905.16 | U25: =(O25*D25)/100000 -> 86.98681 | V25: =(Q25*D25)/100000 -> 57.506478 | W25: =(S25*D25)/100000 -> 126.91085
A26: a | B26: Jordan | C26: 2021 | D26: =114030+119316.5 -> 233346.5 | E26: 11066356 | F26: 3.48 | G26: =(F26/100000)*E26 -> 385.10919 | H26: 2.57 | I26: =(H26/100000)*E26 -> 284.40535 | J26: 4.67 | K26: =(J26/100000)*E26 -> 516.79883 | L26: =(G26/D26)*100000 -> 165.03748 | M26: =(I26/D26)*100000 -> 121.88113 | N26: =(K26/D26)*100000 -> 221.47271 | O26: 6.98 | P26: =(O26/100000)*E26 -> 772.43165 | Q26: 4.49 | R26: =(Q26/100000)*E26 -> 496.87938 | S26: 10.42 | T26: =(S26/100000)*E26 -> 1153.1143 | U26: =(P26/D26)*100000 -> 331.02346 | V26: =(R26/D26)*100000 -> 212.93629 | W26: =(T26/D26)*100000 -> 494.16396
A27: b | B27: Jordan | C27: 2030 | D27: =112693+117975 -> 230668 | E27: 12448776 | F27: 3.48 | G27: =(F27/100000)*E27 -> 433.2174 | H27: 2.57 | I27: =(H27/100000)*E27 -> 319.93354 | J27: 4.67 | K27: =(J27/100000)*E27 -> 581.35784 | L27: =(G27/D27)*100000 -> 187.80993 | M27: =(I27*D27)/100000 -> 737.98431 | N27: =(K27*D27)/100000 -> 1341.0065 | O27: 6.98 | Q27: 4.49 | S27: 10.42 | U27: =(O27*D27)/100000 -> 16.100626 | V27: =(Q27*D27)/100000 -> 10.356993 | W27: =(S27*D27)/100000 -> 24.035606 | Z27: =ROUND(F27, 0) & " (" & ROUND(H27, 0) & "-" & ROUND(J27, 0) & ")" -> 3 (3-5) | AA27: =ROUND(L27, 0) & " (" & ROUND(M27, 0) & "-" & ROUND(N27, 0) & ")" -> 188 (738-1341) | AB27: =ROUND(O27, 0) & " (" & ROUND(Q27, 0) & "-" & ROUND(S27, 0) & ")" -> 7 (4-10) | AC27: =ROUND(U27, 0) & " (" & ROUND(V27, 0) & "-" & ROUND(W27, 0) & ")" -> 16 (10-24)
A28: c | B28: Jordan | C28: 2040 | D28: =122859+128721 -> 251580 | E28: 14471297 | F28: 3.48 | G28: =(F28/100000)*E28 -> 503.60114 | H28: 2.57 | I28: =(H28/100000)*E28 -> 371.91233 | J28: 4.67 | K28: =(J28/100000)*E28 -> 675.80957 | L28: =(G28/D28)*100000 -> 200.17535 | M28: =(I28*D28)/100000 -> 935.65705 | N28: =(K28*D28)/100000 -> 1700.2017 | O28: 6.98 | Q28: 4.49 | S28: 10.42 | U28: =(O28*D28)/100000 -> 17.560284 | V28: =(Q28*D28)/100000 -> 11.295942 | W28: =(S28*D28)/100000 -> 26.214636 | Z28: =ROUND(F28, 0) & " (" & ROUND(H28, 0) & "-" & ROUND(J28, 0) & ")" -> 3 (3-5) | AA28: =ROUND(L28, 0) & " (" & ROUND(M28, 0) & "-" & ROUND(N28, 0) & ")" -> 200 (936-1700) | AB28: =ROUND(O28, 0) & " (" & ROUND(Q28, 0) & "-" & ROUND(S28, 0) & ")" -> 7 (4-10) | AC28: =ROUND(U28, 0) & " (" & ROUND(V28, 0) & "-" & ROUND(W28, 0) & ")" -> 18 (11-26)
A29: d | B29: Jordan | C29: 2050 | D29: =116857+122500 -> 239357 | E29: 16367354 | F29: 3.48 | G29: =(F29/100000)*E29 -> 569.58392 | H29: 2.57 | I29: =(H29/100000)*E29 -> 420.641 | J29: 4.67 | K29: =(J29/100000)*E29 -> 764.35543 | L29: =(G29/D29)*100000 -> 237.96418 | M29: =(I29*D29)/100000 -> 1006.8337 | N29: =(K29*D29)/100000 -> 1829.5382 | O29: 6.98 | P29: =(O29/100000)*E29 -> 1142.4413 | Q29: 4.49 | R29: =(Q29/100000)*E29 -> 734.89419 | S29: 10.42 | T29: =(S29/100000)*E29 -> 1705.4783 | U29: =(O29*D29)/100000 -> 16.707119 | V29: =(Q29*D29)/100000 -> 10.747129 | W29: =(S29*D29)/100000 -> 24.940999
A30: a | B30: Kuwait | C30: 2021 | D30: =27288.5+27818.5 -> 55107 | E30: 4360865 | F30: 1.64 | G30: =(F30/100000)*E30 -> 71.518186 | H30: 1.2 | I30: =(H30/100000)*E30 -> 52.33038 | J30: 2.36 | K30: =(J30/100000)*E30 -> 102.91641 | L30: =(G30/D30)*100000 -> 129.78058 | M30: =(I30/D30)*100000 -> 94.961402 | N30: =(K30/D30)*100000 -> 186.75742 | O30: 5.6 | P30: =(O30/100000)*E30 -> 244.20844 | Q30: 3.43 | R30: =(Q30/100000)*E30 -> 149.57767 | S30: 8.6 | T30: =(S30/100000)*E30 -> 375.03439 | U30: =(P30/D30)*100000 -> 443.15321 | V30: =(R30/D30)*100000 -> 271.43134 | W30: =(T30/D30)*100000 -> 680.55672
A31: b | B31: Kuwait | C31: 2030 | D31: =26186+27312 -> 53498 | E31: 5335372 | F31: 1.64 | G31: =(F31/100000)*E31 -> 87.500101 | H31: 1.2 | I31: =(H31/100000)*E31 -> 64.024464 | J31: 2.36 | K31: =(J31/100000)*E31 -> 125.91478 | L31: =(G31/D31)*100000 -> 163.5577 | M31: =(I31*D31)/100000 -> 34.251808 | N31: =(K31*D31)/100000 -> 67.361889 | O31: 5.6 | Q31: 3.43 | S31: 8.6 | U31: =(O31*D31)/100000 -> 2.995888 | V31: =(Q31*D31)/100000 -> 1.8349814 | W31: =(S31*D31)/100000 -> 4.600828 | Z31: =ROUND(F31, 0) & " (" & ROUND(H31, 0) & "-" & ROUND(J31, 0) & ")" -> 2 (1-2) | AA31: =ROUND(L31, 0) & " (" & ROUND(M31, 0) & "-" & ROUND(N31, 0) & ")" -> 164 (34-67) | AB31: =ROUND(O31, 0) & " (" & ROUND(Q31, 0) & "-" & ROUND(S31, 0) & ")" -> 6 (3-9) | AC31: =ROUND(U31, 0) & " (" & ROUND(V31, 0) & "-" & ROUND(W31, 0) & ")" -> 3 (2-5)
A32: c | B32: Kuwait | C32: 2040 | D32: =30100+31364 -> 61464 | E32: 5839862 | F32: 1.64 | G32: =(F32/100000)*E32 -> 95.773737 | H32: 1.2 | I32: =(H32/100000)*E32 -> 70.078344 | J32: 2.36 | K32: =(J32/100000)*E32 -> 137.82074 | L32: =(G32/D32)*100000 -> 155.82087 | M32: =(I32*D32)/100000 -> 43.072953 | N32: =(K32*D32)/100000 -> 84.710142 | O32: 5.6 | Q32: 3.43 | S32: 8.6 | U32: =(O32*D32)/100000 -> 3.441984 | V32: =(Q32*D32)/100000 -> 2.1082152 | W32: =(S32*D32)/100000 -> 5.285904 | Z32: =ROUND(F32, 0) & " (" & ROUND(H32, 0) & "-" & ROUND(J32, 0) & ")" -> 2 (1-2) | AA32: =ROUND(L32, 0) & " (" & ROUND(M32, 0) & "-" & ROUND(N32, 0) & ")" -> 156 (43-85) | AB32: =ROUND(O32, 0) & " (" & ROUND(Q32, 0) & "-" & ROUND(S32, 0) & ")" -> 6 (3-9) | AC32: =ROUND(U32, 0) & " (" & ROUND(V32, 0) & "-" & ROUND(W32, 0) & ")" -> 3 (2-5)
A33: d | B33: Kuwait | C33: 2050 | D33: =31797+33113 -> 64910 | E33: 6371108 | F33: 1.64 | G33: =(F33/100000)*E33 -> 104.48617 | H33: 1.2 | I33: =(H33/100000)*E33 -> 76.453296 | J33: 2.36 | K33: =(J33/100000)*E33 -> 150.35815 | L33: =(G33/D33)*100000 -> 160.97084 | M33: =(I33*D33)/100000 -> 49.625834 | N33: =(K33*D33)/100000 -> 97.597474 | O33: 5.6 | P33: =(O33/100000)*E33 -> 356.78205 | Q33: 3.43 | R33: =(Q33/100000)*E33 -> 218.529 | S33: 8.6 | T33: =(S33/100000)*E33 -> 547.91529 | U33: =(O33*D33)/100000 -> 3.63496 | V33: =(Q33*D33)/100000 -> 2.226413 | W33: =(S33*D33)/100000 -> 5.58226
A34: a | B34: Lebanon | C34: 2021 | D34: =45698.5+47988.5 -> 93687 | E34: 5718122 | F34: 2.01 | G34: =(F34/100000)*E34 -> 114.93425 | H34: 1.55 | I34: =(H34/100000)*E34 -> 88.630891 | J34: 2.73 | K34: =(J34/100000)*E34 -> 156.10473 | L34: =(G34/D34)*100000 -> 122.67898 | M34: =(I34/D34)*100000 -> 94.60319 | N34: =(K34/D34)*100000 -> 166.62368 | O34: 6.24 | P34: =(O34/100000)*E34 -> 356.81081 | Q34: 4.06 | R34: =(Q34/100000)*E34 -> 232.15575 | S34: 9.05 | T34: =(S34/100000)*E34 -> 517.49004 | U34: =(P34/D34)*100000 -> 380.85413 | V34: =(R34/D34)*100000 -> 247.79932 | W34: =(T34/D34)*100000 -> 552.36056
A35: b | B35: Lebanon | C35: 2030 | D35: =45471+47792 -> 93263 | E35: 6103808 | F35: 2.01 | G35: =(F35/100000)*E35 -> 122.68654 | H35: 1.55 | I35: =(H35/100000)*E35 -> 94.609024 | J35: 2.73 | K35: =(J35/100000)*E35 -> 166.63396 | L35: =(G35/D35)*100000 -> 131.549 | M35: =(I35*D35)/100000 -> 88.235214 | N35: =(K35*D35)/100000 -> 155.40783 | O35: 6.24 | Q35: 4.06 | S35: 9.05 | U35: =(O35*D35)/100000 -> 5.8196112 | V35: =(Q35*D35)/100000 -> 3.7864778 | W35: =(S35*D35)/100000 -> 8.4403015 | Z35: =ROUND(F35, 0) & " (" & ROUND(H35, 0) & "-" & ROUND(J35, 0) & ")" -> 2 (2-3) | AA35: =ROUND(L35, 0) & " (" & ROUND(M35, 0) & "-" & ROUND(N35, 0) & ")" -> 132 (88-155) | AB35: =ROUND(O35, 0) & " (" & ROUND(Q35, 0) & "-" & ROUND(S35, 0) & ")" -> 6 (4-9) | AC35: =ROUND(U35, 0) & " (" & ROUND(V35, 0) & "-" & ROUND(W35, 0) & ")" -> 6 (4-8)
A36: c | B36: Lebanon | C36: 2040 | D36: =47586+50064 -> 97650 | E36: 6620329 | F36: 2.01 | G36: =(F36/100000)*E36 -> 133.06861 | H36: 1.55 | I36: =(H36/100000)*E36 -> 102.6151 | J36: 2.73 | K36: =(J36/100000)*E36 -> 180.73498 | L36: =(G36/D36)*100000 -> 136.27098 | M36: =(I36*D36)/100000 -> 100.20364 | N36: =(K36*D36)/100000 -> 176.48771 | O36: 6.24 | Q36: 4.06 | S36: 9.05 | U36: =(O36*D36)/100000 -> 6.09336 | V36: =(Q36*D36)/100000 -> 3.96459 | W36: =(S36*D36)/100000 -> 8.837325 | Z36: =ROUND(F36, 0) & " (" & ROUND(H36, 0) & "-" & ROUND(J36, 0) & ")" -> 2 (2-3) | AA36: =ROUND(L36, 0) & " (" & ROUND(M36, 0) & "-" & ROUND(N36, 0) & ")" -> 136 (100-176) | AB36: =ROUND(O36, 0) & " (" & ROUND(Q36, 0) & "-" & ROUND(S36, 0) & ")" -> 6 (4-9) | AC36: =ROUND(U36, 0) & " (" & ROUND(V36, 0) & "-" & ROUND(W36, 0) & ")" -> 6 (4-9)
A37: d | B37: Lebanon | C37: 2050 | D37: =42076+44309 -> 86385 | E37: 6999260 | F37: 2.01 | G37: =(F37/100000)*E37 -> 140.68513 | H37: 1.55 | I37: =(H37/100000)*E37 -> 108.48853 | J37: 2.73 | K37: =(J37/100000)*E37 -> 191.0798 | L37: =(G37/D37)*100000 -> 162.85828 | M37: =(I37*D37)/100000 -> 93.717817 | N37: =(K37*D37)/100000 -> 165.06428 | O37: 6.24 | P37: =(O37/100000)*E37 -> 436.75382 | Q37: 4.06 | R37: =(Q37/100000)*E37 -> 284.16996 | S37: 9.05 | T37: =(S37/100000)*E37 -> 633.43303 | U37: =(O37*D37)/100000 -> 5.390424 | V37: =(Q37*D37)/100000 -> 3.507231 | W37: =(S37*D37)/100000 -> 7.8178425
A38: a | B38: Libya | C38: 2021 | D38: =63144.5+66637 -> 129781.5 | E38: 7135175 | F38: 1.5 | G38: =(F38/100000)*E38 -> 107.02763 | H38: 1.15 | I38: =(H38/100000)*E38 -> 82.054513 | J38: 1.98 | K38: =(J38/100000)*E38 -> 141.27647 | L38: =(G38/D38)*100000 -> 82.467551 | M38: =(I38/D38)*100000 -> 63.225123 | N38: =(K38/D38)*100000 -> 108.85717 | O38: 6.37 | P38: =(O38/100000)*E38 -> 454.51065 | Q38: 4.19 | R38: =(Q38/100000)*E38 -> 298.96383 | S38: 9.13 | T38: =(S38/100000)*E38 -> 651.44148 | U38: =(P38/D38)*100000 -> 350.2122 | V38: =(R38/D38)*100000 -> 230.35936 | W38: =(T38/D38)*100000 -> 501.9525
A39: b | B39: Libya | C39: 2030 | D39: =57121+60361 -> 117482 | E39: 7885806 | F39: 1.5 | G39: =(F39/100000)*E39 -> 118.28709 | H39: 1.15 | I39: =(H39/100000)*E39 -> 90.686769 | J39: 1.98 | K39: =(J39/100000)*E39 -> 156.13896 | L39: =(G39/D39)*100000 -> 100.68529 | M39: =(I39*D39)/100000 -> 106.54063 | N39: =(K39*D39)/100000 -> 183.43517 | O39: 6.37 | Q39: 4.19 | S39: 9.13 | U39: =(O39*D39)/100000 -> 7.4836034 | V39: =(Q39*D39)/100000 -> 4.9224958 | W39: =(S39*D39)/100000 -> 10.726107 | Z39: =ROUND(F39, 0) & " (" & ROUND(H39, 0) & "-" & ROUND(J39, 0) & ")" -> 2 (1-2) | AA39: =ROUND(L39, 0) & " (" & ROUND(M39, 0) & "-" & ROUND(N39, 0) & ")" -> 101 (107-183) | AB39: =ROUND(O39, 0) & " (" & ROUND(Q39, 0) & "-" & ROUND(S39, 0) & ")" -> 6 (4-9) | AC39: =ROUND(U39, 0) & " (" & ROUND(V39, 0) & "-" & ROUND(W39, 0) & ")" -> 7 (5-11)
A40: c | B40: Libya | C40: 2040 | D40: =59613+62994 -> 122607 | E40: 8651417 | F40: 1.5 | G40: =(F40/100000)*E40 -> 129.77125 | H40: 1.15 | I40: =(H40/100000)*E40 -> 99.491296 | J40: 1.98 | K40: =(J40/100000)*E40 -> 171.29806 | L40: =(G40/D40)*100000 -> 105.84327 | M40: =(I40*D40)/100000 -> 121.98329 | N40: =(K40*D40)/100000 -> 210.02341 | O40: 6.37 | Q40: 4.19 | S40: 9.13 | U40: =(O40*D40)/100000 -> 7.8100659 | V40: =(Q40*D40)/100000 -> 5.1372333 | W40: =(S40*D40)/100000 -> 11.194019 | Z40: =ROUND(F40, 0) & " (" & ROUND(H40, 0) & "-" & ROUND(J40, 0) & ")" -> 2 (1-2) | AA40: =ROUND(L40, 0) & " (" & ROUND(M40, 0) & "-" & ROUND(N40, 0) & ")" -> 106 (122-210) | AB40: =ROUND(O40, 0) & " (" & ROUND(Q40, 0) & "-" & ROUND(S40, 0) & ")" -> 6 (4-9) | AC40: =ROUND(U40, 0) & " (" & ROUND(V40, 0) & "-" & ROUND(W40, 0) & ")" -> 8 (5-11)
...

Sheet Birth Pop per Year
A1: Country | B1: Year | C1: Birth Population | E1: Country | F1: Year | G1: Birth Population | I1: Country | J1: Year | K1: Birth Population
A2: Afghanistan | B2: 2030 | C2: 1521091 | E2: Afghanistan | F2: 2040 | G2: 1653659 | I2: Afghanistan | J2: 2050 | K2: 1771185
A3: Algeria | B3: 2030 | C3: =374961+391323 -> 766284 | E3: Algeria | F3: 2040 | G3: =401278+419330 -> 820608 | I3: Algeria | J3: 2050 | K3: =419100+438415 -> 857515
A4: Bahrain | B4: 2030 | C4: =10331+10695 -> 21026 | E4: Bahrain | F4: 2040 | G4: =11484+11875 -> 23359 | I4: Bahrain | J4: 2050 | K4: =11965+12358 -> 24323
A5: Egypt | B5: 2030 | C5: =1213206+1278324 -> 2491530 | E5: Egypt | F5: 2040 | G5: =1327238+1399803 -> 2727041 | I5: Egypt | J5: 2050 | K5: =1250892+1319902 -> 2570794
A6: Iran | B6: 2030 | C6: =505962+530579 -> 1036541 | E6: Iran | F6: 2040 | G6: =508605+533053 -> 1041658 | I6: Iran | J6: 2050 | K6: =482638+505938 -> 988576
A7: Iraq | B7: 2030 | C7: =597042+627808 -> 1224850 | E7: Iraq | F7: 2040 | G7: =644831+677866 -> 1322697 | I7: Iraq | J7: 2050 | K7: =644321+677667 -> 1321988
A8: Jordan | B8: 2030 | C8: =112693+117975 -> 230668 | E8: Jordan | F8: 2040 | G8: =122859+128721 -> 251580 | I8: Jordan | J8: 2050 | K8: =116857+122500 -> 239357
A9: Kuwait | B9: 2030 | C9: =26186+27312 -> 53498 | E9: Kuwait | F9: 2040 | G9: =30100+31364 -> 61464 | I9: Kuwait | J9: 2050 | K9: =31797+33113 -> 64910
A10: Lebanon | B10: 2030 | C10: =45471+47792 -> 93263 | E10: Lebanon | F10: 2040 | G10: =47586+50064 -> 97650 | I10: Lebanon | J10: 2050 | K10: =42076+44309 -> 86385
A11: Libya | B11: 2030 | C11: =57121+60361 -> 117482 | E11: Libya | F11: 2040 | G11: =59613+62994 -> 122607 | I11: Libya | J11: 2050 | K11: =56799+60046 -> 116845
A12: Morocco | B12: 2030 | C12: =289365+302361 -> 591726 | E12: Morocco | F12: 2040 | G12: =277438+290105 -> 567543 | I12: Morocco | J12: 2050 | K12: =257893+269957 -> 527850
A13: Oman | B13: 2030 | C13: =43819+45684 -> 89503 | E13: Oman | F13: 2040 | G13: =45562+47538 -> 93100 | I13: Oman | J13: 2050 | K13: =51089+53324 -> 104413
A14: Qatar | B14: 2030 | C14: =16972+17539 -> 34511 | E14: Qatar | F14: 2040 | G14: =21321+22069 -> 43390 | I14: Qatar | J14: 2050 | K14: =24429+25294 -> 49723
A15: Saudi Arabia | B15: 2030 | C15: =281853+295603 -> 577456 | E15: Saudi Arabia | F15: 2040 | G15: =291532+305791 -> 597323 | I15: Saudi Arabia | J15: 2050 | K15: =302075+316779 -> 618854
A16: Sudan | B16: 2030 | C16: =837133+862887 -> 1700020 | E16: Sudan | F16: 2040 | G16: =882132+908446 -> 1790578 | I16: Sudan | J16: 2050 | K16: =949347+977359 -> 1926706
A17: Syrian Arab Republic | B17: 2030 | C17: =327245+343169 -> 670414 | E17: Syrian Arab Republic | F17: 2040 | G17: =285980+299993 -> 585973 | I17: Syrian Arab Republic | J17: 2050 | K17: =260257+273270 -> 533527
A18: Tunisia | B18: 2030 | C18: =71326+74547 -> 145873 | E18: Tunisia | F18: 2040 | G18: =72652+75877 -> 148529 | I18: Tunisia | J18: 2050 | K18: =71659+74896 -> 146555
A19: Turkiye | B19: 2030 | C19: =490176+513619 -> 1003795 | E19: Turkiye | F19: 2040 | G19: =457839+479622 -> 937461 | I19: Turkiye | J19: 2050 | K19: =415696+435490 -> 851186
A20: United Arab Emirates | B20: 2030 | C20: =68352+70233 -> 138585 | E20: United Arab Emirates | F20: 2040 | G20: =82150+84480 -> 166630 | I20: United Arab Emirates | J20: 2050 | K20: =88542+90990 -> 179532
A21: Yemen | B21: 2030 | C21: =670735+705800 -> 1376535 | E21: Yemen | F21: 2040 | G21: =704209+740564 -> 1444773 | I21: Yemen | J21: 2050 | K21: =762677+801902 -> 1564579
A22: Bangladesh | B22: 2030 | C22: =1580072+1653959 -> 3234031 | E22: Bangladesh | F22: 2040 | G22: =1383470+1447859 -> 2831329 | I22: Bangladesh | J22: 2050 | K22: =1327424+1390039 -> 2717463
A23: Bhutan | B23: 2030 | C23: =4652+4865 -> 9517 | E23: Bhutan | F23: 2040 | G23: =4406+4612 -> 9018 | I23: Bhutan | J23: 2050 | K23: =3776+3959 -> 7735
A24: India | B24: 2030 | C24: =10792760+11432189 -> 22224949 | E24: India | F24: 2040 | G24: =10043329+10562288 -> 20605617 | I24: India | J24: 2050 | K24: =9200381+9666706 -> 18867087
A25: Nepal | B25: 2030 | C25: =250788+261549 -> 512337 | E25: Nepal | F25: 2040 | G25: =227694+237303 -> 464997 | I25: Nepal | J25: 2050 | K25: =210639+219686 -> 430325
A26: Pakistan | B26: 2030 | C26: =3342220+3497283 -> 6839503 | E26: Pakistan | F26: 2040 | G26: =3575948+3738612 -> 7314560 | I26: Pakistan | J26: 2050 | K26: =3574115+3735087 -> 7309202
A27: China | B27: 2030 | C27: =4011462+4321904 -> 8333366 | E27: China | F27: 2040 | G27: =4181810+4447348 -> 8629158 | I27: China | J27: 2050 | K27: =3636989+3860534 -> 7497523
A28: North Korea | B28: 2030 | C28: =146125+154669 -> 300794 | E28: North Korea | F28: 2040 | G28: =126473+133845 -> 260318 | I28: North Korea | J28: 2050 | K28: =127887+135359 -> 263246
A29: American Samoa | B29: 2030 | C29: =284+300 -> 584 | E29: American Samoa | F29: 2040 | G29: =284+301 -> 585 | I29: American Samoa | J29: 2050 | K29: =248+263 -> 511
A30: Fiji | B30: 2030 | C30: =7640+8145 -> 15785 | E30: Fiji | F30: 2040 | G30: =7350+7828 -> 15178 | I30: Fiji | J30: 2050 | K30: =6709+7143 -> 13852
A31: Guam | B31: 2030 | C31: =1325+1415 -> 2740 | E31: Guam | F31: 2040 | G31: =1319+1409 -> 2728 | I31: Guam | J31: 2050 | K31: =1337+1430 -> 2767
A32: Kiribati | B32: 2030 | C32: =1577+1674 -> 3251 | E32: Kiribati | F32: 2040 | G32: =1651+1750 -> 3401 | I32: Kiribati | J32: 2050 | K32: =1670+1769 -> 3439
A33: Marshall Islands | B33: 2030 | C33: =283+301 -> 584 | E33: Marshall Islands | F33: 2040 | G33: =279+297 -> 576 | I33: Marshall Islands | J33: 2050 | K33: =210+223 -> 433
A34: Micronesia | B34: 2030 | C34: =1173+1249 -> 2422 | E34: Micronesia | F34: 2040 | G34: =1080+1148 -> 2228 | I34: Micronesia | J34: 2050 | K34: =990+1052 -> 2042
A35: Nauru | B35: 2030 | C35: =138+147 -> 285 | E35: Nauru | F35: 2040 | G35: =155+166 -> 321 | I35: Nauru | J35: 2050 | K35: =153+163 -> 316
A36: Northern Mariana Islands | B36: 2030 | C36: =198+229 -> 427 | E36: Northern Mariana Islands | F36: 2040 | G36: =260+300 -> 560 | I36: Northern Mariana Islands | J36: 2050 | K36: =222+256 -> 478
A37: Palau | B37: 2030 | C37: =86+92 -> 178 | E37: Palau | F37: 2040 | G37: =85+91 -> 176 | I37: Palau | J37: 2050 | K37: =75+81 -> 156
A38: Papua New Guinea | B38: 2030 | C38: =122019+130547 -> 252566 | E38: Papua New Guinea | F38: 2040 | G38: =125842+134553 -> 260395 | I38: Papua New Guinea | J38: 2050 | K38: =127601+136400 -> 264001
A39: Samoa | B39: 2030 | C39: =2591+2781 -> 5372 | E39: Samoa | F39: 2040 | G39: =3019+3239 -> 6258 | I39: Samoa | J39: 2050 | K39: =2873+3085 -> 5958
A40: Solomon Islands | B40: 2030 | C40: =11215+11960 -> 23175 | E40: Solomon Islands | F40: 2040 | G40: =12233+13043 -> 25276 | I40: Solomon Islands | J40: 2050 | K40: =12376+13197 -> 25573
...

Sheet CLP Cases
A1: Country | B1: Adjusted Incidence per Birth Population per 100k in 2021 | C1: Adjusted Incidence Rate per Birth Population per 100k in 2021 (Lower) | D1: Adjusted Incidence Rate per Birth Population per 100k in 2021 (Upper) | E1: 2030 Projected Cases from Birth Population | F1: 2030 Projected Cases from Birth Population (Lower) | G1: 2030 Projected Cases from Birth Population (Upper) | H1: 2040 Projected Cases from Birth Population | I1: 2040 Projected Cases from Birth Population (Lower) | J1: 2040 Projected Cases from Birth Population (Upper) | K1: 2050 Projected Cases from Birth Population | L1: 2050 Projected Cases from Birth Population (Lower) | M1: 2050 Projected Cases from Birth Population (Upper) | N1: Adjusted Rate per Birth Population (95% CI) | O1: Birth Population 2030 | P1: CL/P Estimated 2030 (95% CI) | Q1: Birth Population 2040 | R1: CL/P Estimated 2040 (95% CI) | S1: Birth Population 2050 | T1: CL/P Estimated 2040 (95% CI)
A2: Afghanistan | B2: 180.12141 | C2: 135.16357 | D2: 239.29173 | E2: =(B2/100000)*'Birth Pop per Year'!C2 -> 2739.8106 | F2: =(C2/100000)*'Birth Pop per Year'!C2 -> 2055.9609 | G2: =(D2/100000)*'Birth Pop per Year'!C2 -> 3639.845 | H2: =(B2/100000)*'Birth Pop per Year'!G2 -> 2978.594 | I2: =(C2/100000)*'Birth Pop per Year'!G2 -> 2235.1446 | J2: =(D2/100000)*'Birth Pop per Year'!G2 -> 3957.0693 | K2: =(B2/100000)*'Birth Pop per Year'!K2 -> 3190.2834 | L2: =(C2/100000)*'Birth Pop per Year'!K2 -> 2393.9969 | M2: =(D2/100000)*'Birth Pop per Year'!K2 -> 4238.2993 | N2: =TEXT(ROUND(B2,0),"#,##0") & " (" & TEXT(ROUND(C2,0),"#,##0") & "-" & TEXT(ROUND(D2,0),"#,##0") & ")" -> 180 (135-239) | O2: 1521091 | P2: =TEXT(ROUND(E2,0),"#,##0") & " (" & TEXT(ROUND(F2,0),"#,##0") & "-" & TEXT(ROUND(G2,0),"#,##0") & ")" -> 2,740 (2,056-3,640) | Q2: 1653659 | R2: =TEXT(ROUND(H2,0),"#,##0") & " (" & TEXT(ROUND(I2,0),"#,##0") & "-" & TEXT(ROUND(J2,0),"#,##0") & ")" -> 2,979 (2,235-3,957) | S2: 1771185 | T2: =TEXT(ROUND(K2,0),"#,##0") & " (" & TEXT(ROUND(L2,0),"#,##0") & "-" & TEXT(ROUND(M2,0),"#,##0") & ")" -> 3,190 (2,394-4,238)
A3: Algeria | B3: 140.43557 | C3: 104.85856 | D3: 189.1199 | E3: =(B3/100000)*'Birth Pop per Year'!C3 -> 1076.1353 | F3: =(C3/100000)*'Birth Pop per Year'!G3 -> 860.47771 | G3: =(D3/100000)*'Birth Pop per Year'!C3 -> 1449.1955 | H3: =(B3/100000)*'Birth Pop per Year'!G3 -> 1152.4255 | I3: =(C3/100000)*'Birth Pop per Year'!G3 -> 860.47771 | J3: =(D3/100000)*'Birth Pop per Year'!G3 -> 1551.933 | K3: =(B3/100000)*'Birth Pop per Year'!K3 -> 1204.2561 | L3: =(C3/100000)*'Birth Pop per Year'!K3 -> 899.17786 | M3: =(D3/100000)*'Birth Pop per Year'!K3 -> 1621.7315 | N3: =TEXT(ROUND(B3,0),"#,##0") & " (" & TEXT(ROUND(C3,0),"#,##0") & "-" & TEXT(ROUND(D3,0),"#,##0") & ")" -> 140 (105-189) | O3: =374961+391323 -> 766284 | P3: =TEXT(ROUND(E3,0),"#,##0") & " (" & TEXT(ROUND(F3,0),"#,##0") & "-" & TEXT(ROUND(G3,0),"#,##0") & ")" -> 1,076 (860-1,449) | Q3: =401278+419330 -> 820608 | R3: =TEXT(ROUND(H3,0),"#,##0") & " (" & TEXT(ROUND(I3,0),"#,##0") & "-" & TEXT(ROUND(J3,0),"#,##0") & ")" -> 1,152 (860-1,552) | S3: =419100+438415 -> 857515 | T3: =TEXT(ROUND(K3,0),"#,##0") & " (" & TEXT(ROUND(L3,0),"#,##0") & "-" & TEXT(ROUND(M3,0),"#,##0") & ")" -> 1,204 (899-1,622)
A4: Bahrain | B4: 133.39827 | C4: 99.849002 | D4: 178.92941 | E4: =(B4/100000)*'Birth Pop per Year'!C4 -> 28.048319 | F4: =(C4/100000)*'Birth Pop per Year'!G4 -> 23.323728 | G4: =(D4/100000)*'Birth Pop per Year'!C4 -> 37.621698 | H4: =(B4/100000)*'Birth Pop per Year'!G4 -> 31.160501 | I4: =(C4/100000)*'Birth Pop per Year'!G4 -> 23.323728 | J4: =(D4/100000)*'Birth Pop per Year'!G4 -> 41.796121 | K4: =(B4/100000)*'Birth Pop per Year'!K4 -> 32.44646 | L4: =(C4/100000)*'Birth Pop per Year'!K4 -> 24.286273 | M4: =(D4/100000)*'Birth Pop per Year'!K4 -> 43.521001 | N4: =TEXT(ROUND(B4,0),"#,##0") & " (" & TEXT(ROUND(C4,0),"#,##0") & "-" & TEXT(ROUND(D4,0),"#,##0") & ")" -> 133 (100-179) | O4: =10331+10695 -> 21026 | P4: =TEXT(ROUND(E4,0),"#,##0") & " (" & TEXT(ROUND(F4,0),"#,##0") & "-" & TEXT(ROUND(G4,0),"#,##0") & ")" -> 28 (23-38) | Q4: =11484+11875 -> 23359 | R4: =TEXT(ROUND(H4,0),"#,##0") & " (" & TEXT(ROUND(I4,0),"#,##0") & "-" & TEXT(ROUND(J4,0),"#,##0") & ")" -> 31 (23-42) | S4: =11965+12358 -> 24323 | T4: =TEXT(ROUND(K4,0),"#,##0") & " (" & TEXT(ROUND(L4,0),"#,##0") & "-" & TEXT(ROUND(M4,0),"#,##0") & ")" -> 32 (24-44)
A5: Egypt | B5: 162.39144 | C5: 124.51589 | D5: 217.311 | E5: =(B5/100000)*'Birth Pop per Year'!C5 -> 4046.0316 | F5: =(C5/100000)*'Birth Pop per Year'!G5 -> 3395.5993 | G5: =(D5/100000)*'Birth Pop per Year'!C5 -> 5414.3688 | H5: =(B5/100000)*'Birth Pop per Year'!G5 -> 4428.4813 | I5: =(C5/100000)*'Birth Pop per Year'!G5 -> 3395.5993 | J5: =(D5/100000)*'Birth Pop per Year'!G5 -> 5926.1601 | K5: =(B5/100000)*'Birth Pop per Year'!K5 -> 4174.7495 | L5: =(C5/100000)*'Birth Pop per Year'!K5 -> 3201.047 | M5: =(D5/100000)*'Birth Pop per Year'!K5 -> 5586.6181 | N5: =TEXT(ROUND(B5,0),"#,##0") & " (" & TEXT(ROUND(C5,0),"#,##0") & "-" & TEXT(ROUND(D5,0),"#,##0") & ")" -> 162 (125-217) | O5: =1213206+1278324 -> 2491530 | P5: =TEXT(ROUND(E5,0),"#,##0") & " (" & TEXT(ROUND(F5,0),"#,##0") & "-" & TEXT(ROUND(G5,0),"#,##0") & ")" -> 4,046 (3,396-5,414) | Q5: =1327238+1399803 -> 2727041 | R5: =TEXT(ROUND(H5,0),"#,##0") & " (" & TEXT(ROUND(I5,0),"#,##0") & "-" & TEXT(ROUND(J5,0),"#,##0") & ")" -> 4,428 (3,396-5,926) | S5: =1250892+1319902 -> 2570794 | T5: =TEXT(ROUND(K5,0),"#,##0") & " (" & TEXT(ROUND(L5,0),"#,##0") & "-" & TEXT(ROUND(M5,0),"#,##0") & ")" -> 4,175 (3,201-5,587)
A6: Iran | B6: 108.23338 | C6: 81.906344 | D6: 148.45525 | E6: =(B6/100000)*'Birth Pop per Year'!C6 -> 1121.8834 | F6: =(C6/100000)*'Birth Pop per Year'!G6 -> 853.18399 | G6: =(D6/100000)*'Birth Pop per Year'!C6 -> 1538.7995 | H6: =(B6/100000)*'Birth Pop per Year'!G6 -> 1127.4217 | I6: =(C6/100000)*'Birth Pop per Year'!G6 -> 853.18399 | J6: =(D6/100000)*'Birth Pop per Year'!G6 -> 1546.396 | K6: =(B6/100000)*'Birth Pop per Year'!K6 -> 1069.9693 | L6: =(C6/100000)*'Birth Pop per Year'!K6 -> 809.70646 | M6: =(D6/100000)*'Birth Pop per Year'!K6 -> 1467.593 | N6: =TEXT(ROUND(B6,0),"#,##0") & " (" & TEXT(ROUND(C6,0),"#,##0") & "-" & TEXT(ROUND(D6,0),"#,##0") & ")" -> 108 (82-148) | O6: =505962+530579 -> 1036541 | P6: =TEXT(ROUND(E6,0),"#,##0") & " (" & TEXT(ROUND(F6,0),"#,##0") & "-" & TEXT(ROUND(G6,0),"#,##0") & ")" -> 1,122 (853-1,539) | Q6: =508605+533053 -> 1041658 | R6: =TEXT(ROUND(H6,0),"#,##0") & " (" & TEXT(ROUND(I6,0),"#,##0") & "-" & TEXT(ROUND(J6,0),"#,##0") & ")" -> 1,127 (853-1,546) | S6: =482638+505938 -> 988576 | T6: =TEXT(ROUND(K6,0),"#,##0") & " (" & TEXT(ROUND(L6,0),"#,##0") & "-" & TEXT(ROUND(M6,0),"#,##0") & ")" -> 1,070 (810-1,468)
A7: Iraq | B7: 136.42819 | C7: 100.87184 | D7: 188.2168 | E7: =(B7/100000)*'Birth Pop per Year'!C7 -> 1671.0407 | F7: =(C7/100000)*'Birth Pop per Year'!G7 -> 1334.2287 | G7: =(D7/100000)*'Birth Pop per Year'!C7 -> 2305.3734 | H7: =(B7/100000)*'Birth Pop per Year'!G7 -> 1804.5316 | I7: =(C7/100000)*'Birth Pop per Year'!G7 -> 1334.2287 | J7: =(D7/100000)*'Birth Pop per Year'!G7 -> 2489.5379 | K7: =(B7/100000)*'Birth Pop per Year'!K7 -> 1803.5643 | L7: =(C7/100000)*'Birth Pop per Year'!K7 -> 1333.5136 | M7: =(D7/100000)*'Birth Pop per Year'!K7 -> 2488.2035 | N7: =TEXT(ROUND(B7,0),"#,##0") & " (" & TEXT(ROUND(C7,0),"#,##0") & "-" & TEXT(ROUND(D7,0),"#,##0") & ")" -> 136 (101-188) | O7: =597042+627808 -> 1224850 | P7: =TEXT(ROUND(E7,0),"#,##0") & " (" & TEXT(ROUND(F7,0),"#,##0") & "-" & TEXT(ROUND(G7,0),"#,##0") & ")" -> 1,671 (1,334-2,305) | Q7: =644831+677866 -> 1322697 | R7: =TEXT(ROUND(H7,0),"#,##0") & " (" & TEXT(ROUND(I7,0),"#,##0") & "-" & TEXT(ROUND(J7,0),"#,##0") & ")" -> 1,805 (1,334-2,490) | S7: =644321+677667 -> 1321988 | T7: =TEXT(ROUND(K7,0),"#,##0") & " (" & TEXT(ROUND(L7,0),"#,##0") & "-" & TEXT(ROUND(M7,0),"#,##0") & ")" -> 1,804 (1,334-2,488)
A8: Jordan | B8: 165.03748 | C8: 121.88113 | D8: 221.47271 | E8: =(B8/100000)*'Birth Pop per Year'!C8 -> 380.68866 | F8: =(C8/100000)*'Birth Pop per Year'!G8 -> 306.62854 | G8: =(D8/100000)*'Birth Pop per Year'!C8 -> 510.86668 | H8: =(B8/100000)*'Birth Pop per Year'!G8 -> 415.2013 | I8: =(C8/100000)*'Birth Pop per Year'!G8 -> 306.62854 | J8: =(D8/100000)*'Birth Pop per Year'!G8 -> 557.18105 | K8: =(B8/100000)*'Birth Pop per Year'!K8 -> 395.02877 | L8: =(C8/100000)*'Birth Pop per Year'!K8 -> 291.73101 | M8: =(D8/100000)*'Birth Pop per Year'!K8 -> 530.11044 | N8: =TEXT(ROUND(B8,0),"#,##0") & " (" & TEXT(ROUND(C8,0),"#,##0") & "-" & TEXT(ROUND(D8,0),"#,##0") & ")" -> 165 (122-221) | O8: =112693+117975 -> 230668 | P8: =TEXT(ROUND(E8,0),"#,##0") & " (" & TEXT(ROUND(F8,0),"#,##0") & "-" & TEXT(ROUND(G8,0),"#,##0") & ")" -> 381 (307-511) | Q8: =122859+128721 -> 251580 | R8: =TEXT(ROUND(H8,0),"#,##0") & " (" & TEXT(ROUND(I8,0),"#,##0") & "-" & TEXT(ROUND(J8,0),"#,##0") & ")" -> 415 (307-557) | S8: =116857+122500 -> 239357 | T8: =TEXT(ROUND(K8,0),"#,##0") & " (" & TEXT(ROUND(L8,0),"#,##0") & "-" & TEXT(ROUND(M8,0),"#,##0") & ")" -> 395 (292-530)
A9: Kuwait | B9: 129.78058 | C9: 94.961402 | D9: 186.75742 | E9: =(B9/100000)*'Birth Pop per Year'!C9 -> 69.430016 | F9: =(C9/100000)*'Birth Pop per Year'!G9 -> 58.367076 | G9: =(D9/100000)*'Birth Pop per Year'!C9 -> 99.911487 | H9: =(B9/100000)*'Birth Pop per Year'!G9 -> 79.768338 | I9: =(C9/100000)*'Birth Pop per Year'!G9 -> 58.367076 | J9: =(D9/100000)*'Birth Pop per Year'!G9 -> 114.78858 | K9: =(B9/100000)*'Birth Pop per Year'!K9 -> 84.240577 | L9: =(C9/100000)*'Birth Pop per Year'!K9 -> 61.639446 | M9: =(D9/100000)*'Birth Pop per Year'!K9 -> 121.22424 | N9: =TEXT(ROUND(B9,0),"#,##0") & " (" & TEXT(ROUND(C9,0),"#,##0") & "-" & TEXT(ROUND(D9,0),"#,##0") & ")" -> 130 (95-187) | O9: =26186+27312 -> 53498 | P9: =TEXT(ROUND(E9,0),"#,##0") & " (" & TEXT(ROUND(F9,0),"#,##0") & "-" & TEXT(ROUND(G9,0),"#,##0") & ")" -> 69 (58-100) | Q9: =30100+31364 -> 61464 | R9: =TEXT(ROUND(H9,0),"#,##0") & " (" & TEXT(ROUND(I9,0),"#,##0") & "-" & TEXT(ROUND(J9,0),"#,##0") & ")" -> 80 (58-115) | S9: =31797+33113 -> 64910 | T9: =TEXT(ROUND(K9,0),"#,##0") & " (" & TEXT(ROUND(L9,0),"#,##0") & "-" & TEXT(ROUND(M9,0),"#,##0") & ")" -> 84 (62-121)
A10: Lebanon | B10: 122.67898 | C10: 94.60319 | D10: 166.62368 | E10: =(B10/100000)*'Birth Pop per Year'!C10 -> 114.41409 | F10: =(C10/100000)*'Birth Pop per Year'!G10 -> 92.380015 | G10: =(D10/100000)*'Birth Pop per Year'!C10 -> 155.39825 | H10: =(B10/100000)*'Birth Pop per Year'!G10 -> 119.79602 | I10: =(C10/100000)*'Birth Pop per Year'!G10 -> 92.380015 | J10: =(D10/100000)*'Birth Pop per Year'!G10 -> 162.70803 | K10: =(B10/100000)*'Birth Pop per Year'!K10 -> 105.97623 | L10: =(C10/100000)*'Birth Pop per Year'!K10 -> 81.722966 | M10: =(D10/100000)*'Birth Pop per Year'!K10 -> 143.93787 | N10: =TEXT(ROUND(B10,0),"#,##0") & " (" & TEXT(ROUND(C10,0),"#,##0") & "-" & TEXT(ROUND(D10,0),"#,##0") & ")" -> 123 (95-167) | O10: =45471+47792 -> 93263 | P10: =TEXT(ROUND(E10,0),"#,##0") & " (" & TEXT(ROUND(F10,0),"#,##0") & "-" & TEXT(ROUND(G10,0),"#,##0") & ")" -> 114 (92-155) | Q10: =47586+50064 -> 97650 | R10: =TEXT(ROUND(H10,0),"#,##0") & " (" & TEXT(ROUND(I10,0),"#,##0") & "-" & TEXT(ROUND(J10,0),"#,##0") & ")" -> 120 (92-163) | S10: =42076+44309 -> 86385 | T10: =TEXT(ROUND(K10,0),"#,##0") & " (" & TEXT(ROUND(L10,0),"#,##0") & "-" & TEXT(ROUND(M10,0),"#,##0") & ")" -> 106 (82-144)
A11: Libya | B11: 82.467551 | C11: 63.225123 | D11: 108.85717 | E11: =(B11/100000)*'Birth Pop per Year'!C11 -> 96.884529 | F11: =(C11/100000)*'Birth Pop per Year'!G11 -> 77.518426 | G11: =(D11/100000)*'Birth Pop per Year'!C11 -> 127.88758 | H11: =(B11/100000)*'Birth Pop per Year'!G11 -> 101.11099 | I11: =(C11/100000)*'Birth Pop per Year'!G11 -> 77.518426 | J11: =(D11/100000)*'Birth Pop per Year'!G11 -> 133.46651 | K11: =(B11/100000)*'Birth Pop per Year'!K11 -> 96.35921 | L11: =(C11/100000)*'Birth Pop per Year'!K11 -> 73.875395 | M11: =(D11/100000)*'Birth Pop per Year'!K11 -> 127.19416 | N11: =TEXT(ROUND(B11,0),"#,##0") & " (" & TEXT(ROUND(C11,0),"#,##0") & "-" & TEXT(ROUND(D11,0),"#,##0") & ")" -> 82 (63-109) | O11: =57121+60361 -> 117482 | P11: =TEXT(ROUND(E11,0),"#,##0") & " (" & TEXT(ROUND(F11,0),"#,##0") & "-" & TEXT(ROUND(G11,0),"#,##0") & ")" -> 97 (78-128) | Q11: =59613+62994 -> 122607 | R11: =TEXT(ROUND(H11,0),"#,##0") & " (" & TEXT(ROUND(I11,0),"#,##0") & "-" & TEXT(ROUND(J11,0),"#,##0") & ")" -> 101 (78-133) | S11: =56799+60046 -> 116845 | T11: =TEXT(ROUND(K11,0),"#,##0") & " (" & TEXT(ROUND(L11,0),"#,##0") & "-" & TEXT(ROUND(M11,0),"#,##0") & ")" -> 96 (74-127)
A12: Morocco | B12: 133.54938 | C12: 102.90818 | D12: 176.90956 | E12: =(B12/100000)*'Birth Pop per Year'!C12 -> 790.24638 | F12: =(C12/100000)*'Birth Pop per Year'!G12 -> 584.04816 | G12: =(D12/100000)*'Birth Pop per Year'!C12 -> 1046.8199 | H12: =(B12/100000)*'Birth Pop per Year'!G12 -> 757.95013 | I12: =(C12/100000)*'Birth Pop per Year'!G12 -> 584.04816 | J12: =(D12/100000)*'Birth Pop per Year'!G12 -> 1004.0378 | K12: =(B12/100000)*'Birth Pop per Year'!K12 -> 704.94038 | L12: =(C12/100000)*'Birth Pop per Year'!K12 -> 543.20081 | M12: =(D12/100000)*'Birth Pop per Year'!K12 -> 933.81713 | N12: =TEXT(ROUND(B12,0),"#,##0") & " (" & TEXT(ROUND(C12,0),"#,##0") & "-" & TEXT(ROUND(D12,0),"#,##0") & ")" -> 134 (103-177) | O12: =289365+302361 -> 591726 | P12: =TEXT(ROUND(E12,0),"#,##0") & " (" & TEXT(ROUND(F12,0),"#,##0") & "-" & TEXT(ROUND(G12,0),"#,##0") & ")" -> 790 (584-1,047) | Q12: =277438+290105 -> 567543 | R12: =TEXT(ROUND(H12,0),"#,##0") & " (" & TEXT(ROUND(I12,0),"#,##0") & "-" & TEXT(ROUND(J12,0),"#,##0") & ")" -> 758 (584-1,004) | S12: =257893+269957 -> 527850 | T12: =TEXT(ROUND(K12,0),"#,##0") & " (" & TEXT(ROUND(L12,0),"#,##0") & "-" & TEXT(ROUND(M12,0),"#,##0") & ")" -> 705 (543-934)
A13: Oman | B13: 163.88484 | C13: 119.98711 | D13: 231.77999 | E13: =(B13/100000)*'Birth Pop per Year'!C13 -> 146.68185 | F13: =(C13/100000)*'Birth Pop per Year'!G13 -> 111.708 | G13: =(D13/100000)*'Birth Pop per Year'!C13 -> 207.45004 | H13: =(B13/100000)*'Birth Pop per Year'!G13 -> 152.57679 | I13: =(C13/100000)*'Birth Pop per Year'!G13 -> 111.708 | J13: =(D13/100000)*'Birth Pop per Year'!G13 -> 215.78717 | K13: =(B13/100000)*'Birth Pop per Year'!K13 -> 171.11708 | L13: =(C13/100000)*'Birth Pop per Year'!K13 -> 125.28215 | M13: =(D13/100000)*'Birth Pop per Year'!K13 -> 242.00844 | N13: =TEXT(ROUND(B13,0),"#,##0") & " (" & TEXT(ROUND(C13,0),"#,##0") & "-" & TEXT(ROUND(D13,0),"#,##0") & ")" -> 164 (120-232) | O13: =43819+45684 -> 89503 | P13: =TEXT(ROUND(E13,0),"#,##0") & " (" & TEXT(ROUND(F13,0),"#,##0") & "-" & TEXT(ROUND(G13,0),"#,##0") & ")" -> 147 (112-207) | Q13: =45562+47538 -> 93100 | R13: =TEXT(ROUND(H13,0),"#,##0") & " (" & TEXT(ROUND(I13,0),"#,##0") & "-" & TEXT(ROUND(J13,0),"#,##0") & ")" -> 153 (112-216) | S13: =51089+53324 -> 104413 | T13: =TEXT(ROUND(K13,0),"#,##0") & " (" & TEXT(ROUND(L13,0),"#,##0") & "-" & TEXT(ROUND(M13,0),"#,##0") & ")" -> 171 (125-242)
A14: Qatar | B14: 245.89421 | C14: 176.60444 | D14: 350.67388 | E14: =(B14/100000)*'Birth Pop per Year'!C14 -> 84.860552 | F14: =(C14/100000)*'Birth Pop per Year'!G14 -> 76.628665 | G14: =(D14/100000)*'Birth Pop per Year'!C14 -> 121.02106 | H14: =(B14/100000)*'Birth Pop per Year'!G14 -> 106.6935 | I14: =(C14/100000)*'Birth Pop per Year'!G14 -> 76.628665 | J14: =(D14/100000)*'Birth Pop per Year'!G14 -> 152.1574 | K14: =(B14/100000)*'Birth Pop per Year'!K14 -> 122.26598 | L14: =(C14/100000)*'Birth Pop per Year'!K14 -> 87.813024 | M14: =(D14/100000)*'Birth Pop per Year'!K14 -> 174.36557 | N14: =TEXT(ROUND(B14,0),"#,##0") & " (" & TEXT(ROUND(C14,0),"#,##0") & "-" & TEXT(ROUND(D14,0),"#,##0") & ")" -> 246 (177-351) | O14: =16972+17539 -> 34511 | P14: =TEXT(ROUND(E14,0),"#,##0") & " (" & TEXT(ROUND(F14,0),"#,##0") & "-" & TEXT(ROUND(G14,0),"#,##0") & ")" -> 85 (77-121) | Q14: =21321+22069 -> 43390 | R14: =TEXT(ROUND(H14,0),"#,##0") & " (" & TEXT(ROUND(I14,0),"#,##0") & "-" & TEXT(ROUND(J14,0),"#,##0") & ")" -> 107 (77-152) | S14: =24429+25294 -> 49723 | T14: =TEXT(ROUND(K14,0),"#,##0") & " (" & TEXT(ROUND(L14,0),"#,##0") & "-" & TEXT(ROUND(M14,0),"#,##0") & ")" -> 122 (88-174)
A15: Saudi Arabia | B15: 125.89769 | C15: 91.725459 | D15: 173.85871 | E15: =(B15/100000)*'Birth Pop per Year'!C15 -> 727.00376 | F15: =(C15/100000)*'Birth Pop per Year'!G15 -> 547.89726 | G15: =(D15/100000)*'Birth Pop per Year'!C15 -> 1003.9576 | H15: =(B15/100000)*'Birth Pop per Year'!G15 -> 752.01585 | I15: =(C15/100000)*'Birth Pop per Year'!G15 -> 547.89726 | J15: =(D15/100000)*'Birth Pop per Year'!G15 -> 1038.4981 | K15: =(B15/100000)*'Birth Pop per Year'!K15 -> 779.12288 | L15: =(C15/100000)*'Birth Pop per Year'!K15 -> 567.64667 | M15: =(D15/100000)*'Birth Pop per Year'!K15 -> 1075.9316 | N15: =TEXT(ROUND(B15,0),"#,##0") & " (" & TEXT(ROUND(C15,0),"#,##0") & "-" & TEXT(ROUND(D15,0),"#,##0") & ")" -> 126 (92-174) | O15: =281853+295603 -> 577456 | P15: =TEXT(ROUND(E15,0),"#,##0") & " (" & TEXT(ROUND(F15,0),"#,##0") & "-" & TEXT(ROUND(G15,0),"#,##0") & ")" -> 727 (548-1,004) | Q15: =291532+305791 -> 597323 | R15: =TEXT(ROUND(H15,0),"#,##0") & " (" & TEXT(ROUND(I15,0),"#,##0") & "-" & TEXT(ROUND(J15,0),"#,##0") & ")" -> 752 (548-1,038) | S15: =302075+316779 -> 618854 | T15: =TEXT(ROUND(K15,0),"#,##0") & " (" & TEXT(ROUND(L15,0),"#,##0") & "-" & TEXT(ROUND(M15,0),"#,##0") & ")" -> 779 (568-1,076)
A16: Sudan | B16: 118.26624 | C16: 88.852876 | D16: 154.11378 | E16: =(B16/100000)*'Birth Pop per Year'!C16 -> 2010.5498 | F16: =(C16/100000)*'Birth Pop per Year'!G16 -> 1590.98 | G16: =(D16/100000)*'Birth Pop per Year'!C16 -> 2619.9651 | H16: =(B16/100000)*'Birth Pop per Year'!G16 -> 2117.6493 | I16: =(C16/100000)*'Birth Pop per Year'!G16 -> 1590.98 | J16: =(D16/100000)*'Birth Pop per Year'!G16 -> 2759.5275 | K16: =(B16/100000)*'Birth Pop per Year'!K16 -> 2278.6428 | L16: =(C16/100000)*'Birth Pop per Year'!K16 -> 1711.9337 | M16: =(D16/100000)*'Birth Pop per Year'!K16 -> 2969.3195 | N16: =TEXT(ROUND(B16,0),"#,##0") & " (" & TEXT(ROUND(C16,0),"#,##0") & "-" & TEXT(ROUND(D16,0),"#,##0") & ")" -> 118 (89-154) | O16: =837133+862887 -> 1700020 | P16: =TEXT(ROUND(E16,0),"#,##0") & " (" & TEXT(ROUND(F16,0),"#,##0") & "-" & TEXT(ROUND(G16,0),"#,##0") & ")" -> 2,011 (1,591-2,620) | Q16: =882132+908446 -> 1790578 | R16: =TEXT(ROUND(H16,0),"#,##0") & " (" & TEXT(ROUND(I16,0),"#,##0") & "-" & TEXT(ROUND(J16,0),"#,##0") & ")" -> 2,118 (1,591-2,760) | S16: =949347+977359 -> 1926706 | T16: =TEXT(ROUND(K16,0),"#,##0") & " (" & TEXT(ROUND(L16,0),"#,##0") & "-" & TEXT(ROUND(M16,0),"#,##0") & ")" -> 2,279 (1,712-2,969)
A17: Syrian Arab Republic | B17: 205.95759 | C17: 158.26215 | D17: 277.50075 | E17: =(B17/100000)*'Birth Pop per Year'!C17 -> 1380.7685 | F17: =(C17/100000)*'Birth Pop per Year'!G17 -> 927.37345 | G17: =(D17/100000)*'Birth Pop per Year'!C17 -> 1860.4039 | H17: =(B17/100000)*'Birth Pop per Year'!G17 -> 1206.8559 | I17: =(C17/100000)*'Birth Pop per Year'!G17 -> 927.37345 | J17: =(D17/100000)*'Birth Pop per Year'!G17 -> 1626.0795 | K17: =(B17/100000)*'Birth Pop per Year'!K17 -> 1098.8393 | L17: =(C17/100000)*'Birth Pop per Year'!K17 -> 844.37128 | M17: =(D17/100000)*'Birth Pop per Year'!K17 -> 1480.5414 | N17: =TEXT(ROUND(B17,0),"#,##0") & " (" & TEXT(ROUND(C17,0),"#,##0") & "-" & TEXT(ROUND(D17,0),"#,##0") & ")" -> 206 (158-278) | O17: =327245+343169 -> 670414 | P17: =TEXT(ROUND(E17,0),"#,##0") & " (" & TEXT(ROUND(F17,0),"#,##0") & "-" & TEXT(ROUND(G17,0),"#,##0") & ")" -> 1,381 (927-1,860) | Q17: =285980+299993 -> 585973 | R17: =TEXT(ROUND(H17,0),"#,##0") & " (" & TEXT(ROUND(I17,0),"#,##0") & "-" & TEXT(ROUND(J17,0),"#,##0") & ")" -> 1,207 (927-1,626) | S17: =260257+273270 -> 533527 | T17: =TEXT(ROUND(K17,0),"#,##0") & " (" & TEXT(ROUND(L17,0),"#,##0") & "-" & TEXT(ROUND(M17,0),"#,##0") & ")" -> 1,099 (844-1,481)
A18: Tunisia | B18: 131.37021 | C18: 100.73985 | D18: 175.61406 | E18: =(B18/100000)*'Birth Pop per Year'!C18 -> 191.63366 | F18: =(C18/100000)*'Birth Pop per Year'!G18 -> 149.62789 | G18: =(D18/100000)*'Birth Pop per Year'!C18 -> 256.1735 | H18: =(B18/100000)*'Birth Pop per Year'!G18 -> 195.12286 | I18: =(C18/100000)*'Birth Pop per Year'!G18 -> 149.62789 | J18: =(D18/100000)*'Birth Pop per Year'!G18 -> 260.83781 | K18: =(B18/100000)*'Birth Pop per Year'!K18 -> 192.52961 | L18: =(C18/100000)*'Birth Pop per Year'!K18 -> 147.63928 | M18: =(D18/100000)*'Birth Pop per Year'!K18 -> 257.37119 | N18: =TEXT(ROUND(B18,0),"#,##0") & " (" & TEXT(ROUND(C18,0),"#,##0") & "-" & TEXT(ROUND(D18,0),"#,##0") & ")" -> 131 (101-176) | O18: =71326+74547 -> 145873 | P18: =TEXT(ROUND(E18,0),"#,##0") & " (" & TEXT(ROUND(F18,0),"#,##0") & "-" & TEXT(ROUND(G18,0),"#,##0") & ")" -> 192 (150-256) | Q18: =72652+75877 -> 148529 | R18: =TEXT(ROUND(H18,0),"#,##0") & " (" & TEXT(ROUND(I18,0),"#,##0") & "-" & TEXT(ROUND(J18,0),"#,##0") & ")" -> 195 (150-261) | S18: =71659+74896 -> 146555 | T18: =TEXT(ROUND(K18,0),"#,##0") & " (" & TEXT(ROUND(L18,0),"#,##0") & "-" & TEXT(ROUND(M18,0),"#,##0") & ")" -> 193 (148-257)
A19: Turkiye | B19: 147.13407 | C19: 120.31653 | D19: 222.51311 | E19: =(B19/100000)*'Birth Pop per Year'!C19 -> 1476.9245 | F19: =(C19/100000)*'Birth Pop per Year'!G19 -> 1127.9206 | G19: =(D19/100000)*'Birth Pop per Year'!C19 -> 2233.5754 | H19: =(B19/100000)*'Birth Pop per Year'!G19 -> 1379.3246 | I19: =(C19/100000)*'Birth Pop per Year'!G19 -> 1127.9206 | J19: =(D19/100000)*'Birth Pop per Year'!G19 -> 2085.9736 | K19: =(B19/100000)*'Birth Pop per Year'!K19 -> 1252.3846 | L19: =(C19/100000)*'Birth Pop per Year'!K19 -> 1024.1175 | M19: =(D19/100000)*'Birth Pop per Year'!K19 -> 1894.0004 | N19: =TEXT(ROUND(B19,0),"#,##0") & " (" & TEXT(ROUND(C19,0),"#,##0") & "-" & TEXT(ROUND(D19,0),"#,##0") & ")" -> 147 (120-223) | O19: =490176+513619 -> 1003795 | P19: =TEXT(ROUND(E19,0),"#,##0") & " (" & TEXT(ROUND(F19,0),"#,##0") & "-" & TEXT(ROUND(G19,0),"#,##0") & ")" -> 1,477 (1,128-2,234) | Q19: =457839+479622 -> 937461 | R19: =TEXT(ROUND(H19,0),"#,##0") & " (" & TEXT(ROUND(I19,0),"#,##0") & "-" & TEXT(ROUND(J19,0),"#,##0") & ")" -> 1,379 (1,128-2,086) | S19: =415696+435490 -> 851186 | T19: =TEXT(ROUND(K19,0),"#,##0") & " (" & TEXT(ROUND(L19,0),"#,##0") & "-" & TEXT(ROUND(M19,0),"#,##0") & ")" -> 1,252 (1,024-1,894)
A20: United Arab Emirates | B20: 92.796868 | C20: 65.885776 | D20: 135.48343 | E20: =(B20/100000)*'Birth Pop per Year'!C20 -> 128.60254 | F20: =(C20/100000)*'Birth Pop per Year'!G20 -> 109.78547 | G20: =(D20/100000)*'Birth Pop per Year'!C20 -> 187.75971 | H20: =(B20/100000)*'Birth Pop per Year'!G20 -> 154.62742 | I20: =(C20/100000)*'Birth Pop per Year'!G20 -> 109.78547 | J20: =(D20/100000)*'Birth Pop per Year'!G20 -> 225.75603 | K20: =(B20/100000)*'Birth Pop per Year'!K20 -> 166.60007 | L20: =(C20/100000)*'Birth Pop per Year'!K20 -> 118.28605 | M20: =(D20/100000)*'Birth Pop per Year'!K20 -> 243.23611 | N20: =TEXT(ROUND(B20,0),"#,##0") & " (" & TEXT(ROUND(C20,0),"#,##0") & "-" & TEXT(ROUND(D20,0),"#,##0") & ")" -> 93 (66-135) | O20: =68352+70233 -> 138585 | P20: =TEXT(ROUND(E20,0),"#,##0") & " (" & TEXT(ROUND(F20,0),"#,##0") & "-" & TEXT(ROUND(G20,0),"#,##0") & ")" -> 129 (110-188) | Q20: =82150+84480 -> 166630 | R20: =TEXT(ROUND(H20,0),"#,##0") & " (" & TEXT(ROUND(I20,0),"#,##0") & "-" & TEXT(ROUND(J20,0),"#,##0") & ")" -> 155 (110-226) | S20: =88542+90990 -> 179532 | T20: =TEXT(ROUND(K20,0),"#,##0") & " (" & TEXT(ROUND(L20,0),"#,##0") & "-" & TEXT(ROUND(M20,0),"#,##0") & ")" -> 167 (118-243)
